Workbook

Sheet Sheet1
A1: Company | B1: Year | C1: Assets | D1: Liabilities | E1: Equity(F-G) | F1: Revenue | G1: Operating Expenses | H1: EBITDA | I1: Net Income | J1: EPS | K1: CF-Operations | L1: CF-Investing | M1: CF-Investing N | N1: Free Cash Flow(K-L) | O1: CF - Financing | P1: Free Cash Flow(K-L) | Q1: Stock Price | R1: P/E Ratio(O/J) | S1: Return on Assets(I/F) | T1: Reference Exchange | U1: Volatility(Beta) | V1: Sharpe Ratio
A2: ANTERO RESOURCES Corp | B2: 2013 | C2: 6613581 | D2: 3014921 | E2: =C2-D2 -> 3598660 | F2: 1313134 | G2: 971927 | H2: =F2-G2 -> 341207 | I2: -18930 | J2: -0.09 | K2: 534707 | L2: 2673592 | M2: -2673592 | N2: =K2+M2 -> -2138885 | O2: 2137383 | P2: =K2-L2 -> -2138885 | Q2: 63.15 | R2: =Q2/J2 -> -701.66667 | S2: =I2/C2 -> -0.002862292 | T2: NASDAQ
A3: ANTERO RESOURCES Corp | B3: 2014 | C3: 11573495 | D3: 6099665 | E3: =C3-D3 -> 5473830 | F3: 2720632 | G3: 1420898 | H3: =F3-G3 -> 1299734 | I3: 673587 | J3: 2.57 | K3: 998121 | L3: 4089650 | M3: -4089650 | N3: =K3+M3 -> -3091529 | O3: 3320021 | P3: =K3-L3 -> -3091529 | Q3: 40.6 | R3: =Q3/J3 -> 15.797665 | S3: =I3/C3 -> 0.058200829 | T3: NASDAQ
A4: ANTERO RESOURCES Corp | B4: 2015 | C4: 14155224 | D4: 6868546 | E4: =C4-D4 -> 7286678 | F4: 3954858 | G4: 2164572 | H4: =F4-G4 -> 1790286 | I4: 941364 | J4: 3.43 | K4: 1006381 | L4: 2298159 | M4: -2298159 | N4: =K4+M4 -> -1291778 | O4: 1069272 | P4: =K4-L4 -> -1291778 | Q4: 21.75 | R4: =Q4/J4 -> 6.3411079 | S4: =I4/C4 -> 0.066502939 | T4: NASDAQ
A5: ANTERO RESOURCES Corp | B5: 2016 | C5: 14255550 | D5: 6526972 | E5: =C5-D5 -> 7728578 | F5: 1744525 | G5: 2720326 | H5: =F5-G5 -> -975801 | I5: -848816 | J5: -2.88 | K5: 1241256 | L5: 2395138 | M5: -2395138 | N5: =K5+M5 -> -1153882 | O5: 1162019 | P5: =K5-L5 -> -1153882 | Q5: 23.89 | R5: =Q5/J5 -> -8.2951389 | S5: =I5/C5 -> -0.059542845 | T5: NASDAQ
A6: ANTERO RESOURCES Corp | B6: 2017 | C6: 15261490 | D6: 6385354 | E6: =C6-D6 -> 8876136 | F6: 3655574 | G6: 2915481 | H6: =F6-G6 -> 740093 | I6: 615070 | J6: 1.95 | K6: 2006291 | L6: 2461630 | M6: -2461630 | N6: =K6+M6 -> -455339 | O6: 452170 | P6: =K6-L6 -> -455339 | Q6: 19.24 | R6: =Q6/J6 -> 9.8666667 | S6: =I6/C6 -> 0.040302094 | T6: NASDAQ
A7: ANTERO RESOURCES Corp | B7: 2018 | C7: 15519464 | D7: 7031987 | E7: =C7-D7 -> 8487477 | F7: 4139626 | G7: 4067721 | H7: =F7-G7 -> 71905 | I7: -397517 | J7: -1.26 | K7: 2081987 | L7: 2350724 | M7: -2350724 | N7: =K7+M7 -> -268737 | O7: 240296 | P7: =K7-L7 -> -268737 | Q7: 9.2 | R7: =Q7/J7 -> -7.3015873 | S7: =I7/C7 -> -0.025614093 | T7: NASDAQ
A8: ANTERO RESOURCES Corp | B8: 2019 | C8: 15197569 | D8: 8226826 | E8: =C8-D8 -> 6970743 | F8: 4408690 | G8: 5395735 | H8: =F8-G8 -> -987045 | I8: -340129 | J8: -1.11 | K8: 1103458 | L8: 1041490 | M8: -1041490 | N8: =K8+M8 -> 61968 | O8: 557564 | P8: =K8-L8 -> 61968 | Q8: 2.88 | R8: =Q8/J8 -> -2.5945946 | S8: =I8/C8 -> -0.022380487 | T8: NASDAQ
A9: ANTERO RESOURCES Corp | B9: 2020 | C9: 13150845 | D9: 7060574 | E9: =C9-D9 -> 6090271 | F9: 3491699 | G9: 4445146 | H9: =F9-G9 -> -953447 | I9: -1267897 | J9: -4.65 | K9: 735640 | L9: 530061 | M9: -530061 | N9: =K9+M9 -> 205579 | O9: -205579 | P9: =K9-L9 -> 205579 | Q9: 5.57 | R9: =Q9/J9 -> -1.1978495 | S9: =I9/C9 -> -0.096411828 | T9: NASDAQ
A10: ANTERO RESOURCES Corp | B10: 2021 | C10: 13896528 | D10: 7830436 | E10: =C10-D10 -> 6066092 | F10: 4619432 | G10: 4595572 | H10: =F10-G10 -> 23860 | I10: -186899 | J10: -0.61 | K10: 1660116 | L10: 710784 | M10: -710784 | N10: =K10+M10 -> 949332 | O10: -949332 | P10: =K10-L10 -> 949332 | Q10: 17.33 | R10: =Q10/J10 -> -28.409836 | S10: =I10/C10 -> -0.013449331 | T10: NASDAQ
A11: ANTERO RESOURCES Corp | B11: 2022 | C11: 14118039 | D11: 7100885 | E11: =C11-D11 -> 7017154 | F11: 7138436 | G11: 4564531 | H11: =F11-G11 -> 2573905 | I11: 1898771 | J11: 6.18 | K11: 3051342 | L11: 943612 | M11: -943612 | N11: =K11+M11 -> 2107730 | O11: -2107730 | P11: =K11-L11 -> 2107730 | Q11: 29.95 | R11: =Q11/J11 -> 4.8462783 | S11: =I11/C11 -> 0.13449255 | T11: NASDAQ
A12: Callon Petroleum | B12: 2012 | C12: 378173 | D12: 172202 | E12: =C12-D12 -> 205971 | F12: 110733 | G12: 100043 | H12: =F12-G12 -> 10690 | I12: 2747 | J12: 0.07 | K12: 51290 | L12: 93703 | M12: -93703 | N12: =K12+M12 -> -42413 | O12: -243 | P12: =K12-L12 -> -42413 | Q12: 62.9 | R12: =Q12/J12 -> 898.57143 | S12: =I12/C12 -> 0.0072638713 | T12: NASDAQ
A13: Callon Petroleum | B13: 2013 | C13: 423953 | D13: 144859 | E13: =C13-D13 -> 279094 | F13: 102569 | G13: 91905 | H13: =F13-G13 -> 10664 | I13: -323 | J13: -0.01 | K13: 54329 | L13: 79804 | M13: -79804 | N13: =K13+M13 -> -25475 | O13: 27348 | P13: =K13-L13 -> -25475 | Q13: 37 | R13: =Q13/J13 -> -3700 | S13: =I13/C13 -> -0.00076187691 | T13: NASDAQ
... A19: Callon Petroleum | B19: 2019 | C19: 7194838 | D19: 3971530 | E19: =C19-D19 -> 3223308 | F19: 671572 | G19: 498914 | H19: =F19-G19 -> 172658 | I19: 55627 | J19: 0.24 | K19: 476316 | L19: 388389 | M19: -388389 | N19: =K19+M19 -> 87927 | O19: -90637 | P19: =K19-L19 -> 87927 | Q19: 75.5 | R19: =Q19/J19 -> 314.58333 | S19: =I19/C19 -> 0.0077315153 | T19: NASDAQ
A20: Callon Petroleum | B20: 2020 | C20: 4362868 | D20: 3651866 | E20: =C20-D20 -> 711002 | F20: 1033147 | G20: 3489999 | H20: =F20-G20 -> -2456852 | I20: -2533621 | J20: =-(63.79) -> -63.79 | K20: 559775 | L20: 529883 | M20: -529883 | N20: =K20+M20 -> 29892 | O20: 22997 | P20: =K20-L20 -> 29892 | Q20: 5.48 | R20: =Q20/J20 -> -0.085906882 | S20: =I20/C20 -> -0.58072373 | T20: NASDAQ
A21: Callon Petroleum | B21: 2021 | C21: 5547503 | D21: 3681735 | E21: =C21-D21 -> 1865768 | F21: 2045030 | G21: 1034977 | H21: =F21-G21 -> 1010053 | I21: 365151 | J21: 7.51 | K21: 974143 | L21: 876400 | M21: -876400 | N21: =K21+M21 -> 97743 | O21: 108097 | P21: =K21-L21 -> 97743 | Q21: 38.6 | R21: =Q21/J21 -> 5.1398136 | S21: =I21/C21 -> 0.065822587 | T21: NASDAQ
A22: Callon Petroleum | B22: 2022 | C22: 6146081 | D22: 3060659 | E22: =C22-D22 -> 3085422 | F22: 3230964 | G22: 1550432 | H22: =F22-G22 -> 1680532 | I22: 1209816 | J22: 19.63 | K22: 1501517 | L22: 999027 | M22: -999027 | N22: =K22+M22 -> 502490 | O22: -508977 | P22: =K22-L22 -> 502490 | Q22: 59.08 | R22: =Q22/J22 -> 3.0096791 | S22: =I22/C22 -> 0.19684348 | T22: NASDAQ
A23: Chesapeake Energy | B23: 2012 | C23: 41611000 | D23: 23715000 | E23: 17896000 | F23: 12316000 | G23: 14010000 | H23: -1694000 | I23: -940000 | J23: -1.46 | K23: 2837000 | L23: 4984000 | M23: -4984000 | N23: =K23+M23 -> -2147000 | O23: 2083000 | P23: =K23-L23 -> -2147000 | Q23: 0 | R23: =Q23/J23 -> 0 | S23: =I23/F23 -> -0.076323482 | T23: NASDAQ
A24: Chesapeake Energy | B24: 2013 | C24: 41782000 | D24: 23642000 | E24: 18140000 | F24: 17506000 | G24: 15437000 | H24: 2069000 | I24: 474000 | J24: 0.73 | K24: 4614000 | L24: 2967000 | M24: -2967000 | N24: =K24+M24 -> 1647000 | O24: -1097000 | P24: =K24-L24 -> 1647000 | Q24: 0 | R24: =Q24/J24 -> 0 | S24: =I24/C24 -> 0.011344598 | T24: NASDAQ
A25: Chesapeake Energy | B25: 2014 | C25: 40751000 | D25: 22546000 | E25: 18205000 | F25: 20951000 | G25: 17474000 | H25: 3477000 | I25: 1273000 | J25: 1.93 | K25: 4634000 | L25: 454000 | M25: -454000 | N25: =K25+M25 -> 4180000 | O25: -1817000 | P25: =K25-L25 -> 4180000 | Q25: 0 | R25: =Q25/J25 -> 0 | S25: =I25/C25 -> 0.031238497 | T25: NASDAQ
A26: Chesapeake Energy | B26: 2015 | C26: 17357000 | D26: 14960000 | E26: 2397000 | F26: 12764000 | G26: 31683000 | H26: -18919000 | I26: -14856000 | J26: -22.43 | K26: 1234000 | L26: 3451000 | M26: -3451000 | N26: =K26+M26 -> -2217000 | O26: -1066000 | P26: =K26-L26 -> -2217000 | Q26: 0 | R26: =Q26/J26 -> 0 | S26: =I26/C26 -> -0.85590828 | T26: NASDAQ
A27: Chesapeake Energy | B27: 2016 | C27: 13028000 | D27: 14231000 | E27: -1203000 | F27: 7872000 | G27: 12283000 | H27: -4411000 | I27: -4926000 | J27: -6.45 | K27: -204000 | L27: 660000 | M27: -660000 | N27: =K27+M27 -> -864000 | O27: 921000 | P27: =K27-L27 -> -864000 | Q27: 0 | R27: =Q27/J27 -> 0 | S27: =I27/C27 -> -0.37810869 | T27: NASDAQ
A28: Chesapeake Energy | B28: 2017 | C28: 12425000 | D28: 12797000 | E28: -372000 | F28: 9496000 | G28: 8357000 | H28: 1139000 | I28: 813000 | J28: 0.9 | K28: 745000 | L28: 1188000 | M28: -1188000 | N28: =K28+M28 -> -443000 | O28: -434000 | P28: =K28-L28 -> -443000 | Q28: 0 | R28: =Q28/J28 -> 0 | S28: =I28/C28 -> 0.065432596 | T28: NASDAQ
A29: Chesapeake Energy | B29: 2018 | C29: 10947000 | D29: 10480000 | E29: 467000 | F29: 10231000 | G29: 9349000 | H29: 882000 | I29: 775000 | J29: 0.85 | K29: 2000000 | L29: 185000 | M29: -185000 | N29: =K29+M29 -> 1815000 | O29: -2186000 | P29: =K29-L29 -> 1815000 | Q29: 0 | R29: =Q29/J29 -> 0 | S29: =I29/C29 -> 0.070795652 | T29: NASDAQ
A30: Chesapeake Energy | B30: 2019 | C30: 16193000 | D30: 11792000 | E30: 4401000 | F30: 8595000 | G30: 8626000 | H30: -31000 | I30: -416000 | J30: -0.25 | K30: 1623000 | L30: 2480000 | M30: -2480000 | N30: =K30+M30 -> -857000 | O30: 859000 | P30: =K30-L30 -> -857000 | Q30: 0 | R30: =Q30/J30 -> 0 | S30: =I30/C30 -> -0.025690113 | T30: NASDAQ
A31: Chesapeake Energy | B31: 2020 | C31: 6584000 | D31: 11925000 | E31: -5341000 | F31: 5296000 | G31: 13999000 | H31: -8703000 | I31: -9750000 | J31: -998.26 | K31: 1164000 | L31: 992000 | M31: -992000 | N31: =K31+M31 -> 172000 | O31: 101000 | P31: =K31-L31 -> 172000 | Q31: 0 | R31: =Q31/J31 -> 0 | S31: =I31/C31 -> -1.4808627 | T31: NASDAQ
A32: Chesapeake Energy | B32: 2021 | C32: 11009000 | D32: 5338000 | E32: 5671000 | F32: 5549000 | G32: 4611000 | H32: 938000 | I32: 945000 | J32: 9.29 | K32: 1809000 | L32: 850000 | M32: -850000 | N32: =K32+M32 -> 959000 | O32: -171000 | P32: =K32-L32 -> 959000 | Q32: 0 | R32: =Q32/J32 -> 0 | S32: =I32/C32 -> 0.085838859 | T32: NASDAQ
A33: Chesapeake Energy | B33: 2022 | C33: 15468000 | D33: 6344000 | E33: 9124000 | F33: 11743000 | G33: 7963000 | H33: 3780000 | I33: 4936000 | J33: 38.71 | K33: 4125000 | L33: 3401000 | M33: -3401000 | N33: =K33+M33 -> 724000 | O33: -1446000 | P33: =K33-L33 -> 724000 | Q33: 0 | R33: =Q33/J33 -> 0 | S33: =I33/C33 -> 0.31911042 | T33: NASDAQ
A34: Chord Energy | B34: 2022 | C34: 6631081 | D34: 1951283 | E34: =C34-D34 -> 4679798 | F34: 3646794 | G34: =2067872-4867 -> 2063005 | H34: =F34-G34 -> 1583789 | I34: 1856159 | J34: 60.86 | K34: 1924026 | L34: 682562 | M34: -682562 | N34: =K34+M34 -> 1241464 | O34: -823096 | P34: =K34-L34 -> 1241464 | Q34: 146.3 | R34: =Q34/J34 -> 2.4038778 | S34: =I34/C34 -> 0.27991801 | T34: NASDAQ
A35: Civitas Resources | B35: 2021 | C35: 6741033 | D35: 2086035 | E35: =C35-D35 -> 4654998 | F35: 930614 | G35: 608551 | H35: =F35-G35 -> 322063 | I35: 178921 | J35: 4.82 | K35: 274599 | L35: -73547 | M35: 73547 | N35: =K35+M35 -> 348146 | O35: -118435 | P35: =K35-L35 -> 348146 | Q35: 35.73 | R35: =Q35/J35 -> 7.4128631 | S35: =I35/C35 -> 0.026542074 | T35: NASDAQ
A36: Civitas Resources | B36: 2022 | C36: 7971399 | D36: 1177927 | E36: =C36-D36 -> 6793472 | F36: 3791398 | G36: 1807358 | H36: =F36-G36 -> 1984040 | I36: 1248080 | J36: 14.68 | K36: 2477041 | L36: 1306095 | M36: -1306095 | N36: =K36+M36 -> 1170946 | O36: -657368 | P36: =K36-L36 -> 1170946 | Q36: 59.71 | R36: =Q36/J36 -> 4.0674387 | S36: =I36/C36 -> 0.15656976 | T36: NASDAQ
A37: ConocoPhillips | B37: 2012 | C37: 117144000 | D37: =68717000 -> 68717000 | E37: =C37-D37 -> 48427000 | F37: 62004000 | G37: 46581000 | H37: =F37-G37 -> 15423000 | I37: 8428000 | J37: 6.77 | K37: 13922000 | L37: 11627000 | M37: -11627000 | N37: =K37+M37 -> 2295000 | O37: -4481 | P37: =K37-L37 -> 2295000 | Q37: 57.94 | R37: =Q37/J37 -> 8.5583456 | S37: =I37/C37 -> 0.07194564 | T37: NASDAQ
A38: ConocoPhillips | B38: 2013 | C38: 118057000 | D38: 65565000 | E38: =C38-D38 -> 52492000 | F38: 58248000 | G38: 43802000 | H38: =F38-G38 -> 14446000 | I38: 9156000 | J38: 7.43 | K38: 16087000 | L38: 6251000 | M38: -6251000 | N38: =K38+M38 -> 9836000 | O38: -7133000 | P38: =K38-L38 -> 9836000 | Q38: 60.1 | R38: =Q38/J38 -> 8.0888291 | S38: =I38/C38 -> 0.077555757 | T38: NASDAQ
A39: ConocoPhillips | B39: 2014 | C39: 116539000 | D39: 64266000 | E39: =C39-D39 -> 52273000 | F39: 55517000 | G39: 46127000 | H39: =F39-G39 -> 9390000 | I39: -6869 | J39: 5.54 | K39: 16735000 | L39: 15131000 | M39: -15131000 | N39: =K39+M39 -> 1604000 | O39: 2574000 | P39: =K39-L39 -> 1604000 | Q39: 70.35 | R39: =Q39/J39 -> 12.698556 | S39: =I39/C39 -> -5.8941642e-05 | T39: NASDAQ
A40: ConocoPhillips | B40: 2015 | C40: 97484000 | D40: 57402000 | E40: =C40-D40 -> 40082000 | F40: 30935000 | G40: 38174000 | H40: =F40-G40 -> -7239000 | I40: -4428000 | J40: -3.58 | K40: 7572000 | L40: 8655000 | M40: -8655000 | N40: =K40+M40 -> -1083000 | O40: -1429000 | P40: =K40-L40 -> -1083000 | Q40: 62.26 | R40: =Q40/J40 -> -17.391061 | S40: =I40/C40 -> -0.045422839 | T40: NASDAQ
A41: ConocoPhillips | B41: 2016 | C41: 89772000 | D41: 54546000 | E41: =C41-D41 -> 35226000 | F41: 24360000 | G41: 29890000 | H41: =F41-G41 -> -5530000 | I41: -3615000 | J41: -2.91 | K41: 4403000 | L41: 3859000 | M41: -3859000 | N41: =K41+M41 -> 544000 | O41: 764000 | P41: =K41-L41 -> 544000 | Q41: 40.27 | R41: =Q41/J41 -> -13.838488 | S41: =I41/C41 -> -0.040268681 | T41: NASDAQ
A42: ConocoPhillips | B42: 2017 | C42: 73362000 | D42: 42561000 | E42: =C42-D42 -> 30801000 | F42: 32584000 | G42: 35199000 | H42: =F42-G42 -> -2615000 | I42: -855000 | J42: -0.7 | K42: 7077000 | L42: -7762000 | M42: 7762000 | N42: =K42+M42 -> 14839000 | O42: -12356000 | P42: =K42-L42 -> 14839000 | Q42: 49.87 | R42: =Q42/J42 -> -71.242857 | S42: =I42/C42 -> -0.011654535 | T42: NASDAQ
A43: ConocoPhillips | B43: 2018 | C43: 69980000 | D43: 37916000 | E43: =C43-D43 -> 32064000 | F43: 38727000 | G43: 28754000 | H43: =F43-G43 -> 9973000 | I43: 6305000 | J43: 5.36 | K43: 12934000 | L43: 3843000 | M43: -3843000 | N43: =K43+M43 -> 9091000 | O43: -9359000 | P43: =K43-L43 -> 9091000 | Q43: 59.29 | R43: =Q43/J43 -> 11.061567 | S43: =I43/C43 -> 0.090097171 | T43: NASDAQ
A44: ConocoPhillips | B44: 2019 | C44: 70514000 | D44: 35464000 | E44: =C44-D44 -> 35050000 | F44: 36670000 | G44: 27146000 | H44: =F44-G44 -> 9524000 | I44: 7189000 | J44: 6.43 | K44: 11104000 | L44: 6618000 | M44: -6618000 | N44: =K44+M44 -> 4486000 | O44: -5229000 | P44: =K44-L44 -> 4486000 | Q44: 66.74 | R44: =Q44/J44 -> 10.379471 | S44: =I44/F44 -> 0.19604581 | T44: NASDAQ
A45: ConocoPhillips | B45: 2020 | C45: 22396000 | D45: 32769000 | E45: =C45-D45 -> -10373000 | F45: 19256000 | G45: 22396000 | H45: =F45-G45 -> -3140000 | I45: -2701000 | J45: -2.51 | K45: 4802000 | L45: 4121000 | M45: -4121000 | N45: =K45+M45 -> 681000 | O45: -2708000 | P45: =K45-L45 -> 681000 | Q45: 30.8 | R45: =Q45/J45 -> -12.270916 | S45: =I45/F45 -> -0.14026797 | T45: NASDAQ
...

Sheet Sheet3
M9: =(325737/500) -> 651.474 | P9: =53*(1+0.1)^(2024-2001) -> 474.57803
M10: =M9^(1/(2024-2001)) -> 1.325389 | P10: =53*(1+0.2)^(2024-2001) -> 3511.1108
M11: =M10-1 -> 0.32538897 | P11: =53*(1+0.3)^(2024-2001) -> 22129.57
P12: =53*(1+0.4)^(2024-2001) -> 121680.42
P13: =53*(1+0.46)^(2024-2001) -> 319441.66

Sheet SQL
A1: SQL
A2: =CONCATENATE("(N","'",Sheet1!A2,"',",Sheet1!B2,",",Sheet1!C2,",",SQL!D2,Sheet1!D2,",",Sheet1!E2,",",Sheet1!F2,",",Sheet1!G2,",",Sheet1!H2,",",Sheet1!I2,",",Sheet1!J2,",",Sheet1!K2,",",Sheet1!M2,",",Sheet1!N2,",",Sheet1!O2,",",Sheet1!Q2,",",Sheet1!R2,",",Sheet1!S2,",N'",Sheet1!T2,"',","Null",",","Null",$B$2,"),") -> (N'ANTERO RESOURCES Corp',2013,6613581,3014921,3598660,1313134,971927,341207,-18930,-0.09,534707,-2673592,-2138885,2137383,63.15,-701.666666666667,-0.00286229200186707,N'NASDAQ',Null,Null ,CURRENT_TIMESTAMP, N'Mohan Hanumantha',CURRENT_TIMESTAMP, N'Mohan Hanumantha'), | B2: ,CURRENT_TIMESTAMP, N'Mohan Hanumantha',CURRENT_TIMESTAMP, N'Mohan Hanumantha'
A3: =CONCATENATE("(N","'",Sheet1!A3,"',",Sheet1!B3,",",Sheet1!C3,",",SQL!D3,Sheet1!D3,",",Sheet1!E3,",",Sheet1!F3,",",Sheet1!G3,",",Sheet1!H3,",",Sheet1!I3,",",Sheet1!J3,",",Sheet1!K3,",",Sheet1!M3,",",Sheet1!N3,",",Sheet1!O3,",",Sheet1!Q3,",",Sheet1!R3,",",Sheet1!S3,",N'",Sheet1!T3,"',","Null",",","Null",$B$2,"),") -> (N'ANTERO RESOURCES Corp',2014,11573495,6099665,5473830,2720632,1420898,1299734,673587,2.57,998121,-4089650,-3091529,3320021,40.6,15.7976653696498,0.0582008287038617,N'NASDAQ',Null,Null ,CURRENT_TIMESTAMP, N'Mohan Hanumantha',CURRENT_TIMESTAMP, N'Mohan Hanumantha'),
A4: =CONCATENATE("(N","'",Sheet1!A4,"',",Sheet1!B4,",",Sheet1!C4,",",SQL!D4,Sheet1!D4,",",Sheet1!E4,",",Sheet1!F4,",",Sheet1!G4,",",Sheet1!H4,",",Sheet1!I4,",",Sheet1!J4,",",Sheet1!K4,",",Sheet1!M4,",",Sheet1!N4,",",Sheet1!O4,",",Sheet1!Q4,",",Sheet1!R4,",",Sheet1!S4,",N'",Sheet1!T4,"',","Null",",","Null",$B$2,"),") -> (N'ANTERO RESOURCES Corp',2015,14155224,6868546,7286678,3954858,2164572,1790286,941364,3.43,1006381,-2298159,-1291778,1069272,21.75,6.34110787172012,0.0665029391269259,N'NASDAQ',Null,Null ,CURRENT_TIMESTAMP, N'Mohan Hanumantha',CURRENT_TIMESTAMP, N'Mohan Hanumantha'),
A5: =CONCATENATE("(N","'",Sheet1!A5,"',",Sheet1!B5,",",Sheet1!C5,",",SQL!D5,Sheet1!D5,",",Sheet1!E5,",",Sheet1!F5,",",Sheet1!G5,",",Sheet1!H5,",",Sheet1!I5,",",Sheet1!J5,",",Sheet1!K5,",",Sheet1!M5,",",Sheet1!N5,",",Sheet1!O5,",",Sheet1!Q5,",",Sheet1!R5,",",Sheet1!S5,",N'",Sheet1!T5,"',","Null",",","Null",$B$2,"),") -> (N'ANTERO RESOURCES Corp',2016,14255550,6526972,7728578,1744525,2720326,-975801,-848816,-2.88,1241256,-2395138,-1153882,1162019,23.89,-8.29513888888889,-0.0595428447166191,N'NASDAQ',Null,Null ,CURRENT_TIMESTAMP, N'Mohan Hanumantha',CURRENT_TIMESTAMP, N'Mohan Hanumantha'),
A6: =CONCATENATE("(N","'",Sheet1!A6,"',",Sheet1!B6,",",Sheet1!C6,",",SQL!D6,Sheet1!D6,",",Sheet1!E6,",",Sheet1!F6,",",Sheet1!G6,",",Sheet1!H6,",",Sheet1!I6,",",Sheet1!J6,",",Sheet1!K6,",",Sheet1!M6,",",Sheet1!N6,",",Sheet1!O6,",",Sheet1!Q6,",",Sheet1!R6,",",Sheet1!S6,",N'",Sheet1!T6,"',","Null",",","Null",$B$2,"),") -> (N'ANTERO RESOURCES Corp',2017,15261490,6385354,8876136,3655574,2915481,740093,615070,1.95,2006291,-2461630,-455339,452170,19.24,9.86666666666667,0.0403020937012048,N'NASDAQ',Null,Null ,CURRENT_TIMESTAMP, N'Mohan Hanumantha',CURRENT_TIMESTAMP, N'Mohan Hanumantha'),
A7: =CONCATENATE("(N","'",Sheet1!A7,"',",Sheet1!B7,",",Sheet1!C7,",",SQL!D7,Sheet1!D7,",",Sheet1!E7,",",Sheet1!F7,",",Sheet1!G7,",",Sheet1!H7,",",Sheet1!I7,",",Sheet1!J7,",",Sheet1!K7,",",Sheet1!M7,",",Sheet1!N7,",",Sheet1!O7,",",Sheet1!Q7,",",Sheet1!R7,",",Sheet1!S7,",N'",Sheet1!T7,"',","Null",",","Null",$B$2,"),") -> (N'ANTERO RESOURCES Corp',2018,15519464,7031987,8487477,4139626,4067721,71905,-397517,-1.26,2081987,-2350724,-268737,240296,9.2,-7.3015873015873,-0.0256140933733278,N'NASDAQ',Null,Null ,CURRENT_TIMESTAMP, N'Mohan Hanumantha',CURRENT_TIMESTAMP, N'Mohan Hanumantha'),
A8: =CONCATENATE("(N","'",Sheet1!A8,"',",Sheet1!B8,",",Sheet1!C8,",",SQL!D8,Sheet1!D8,",",Sheet1!E8,",",Sheet1!F8,",",Sheet1!G8,",",Sheet1!H8,",",Sheet1!I8,",",Sheet1!J8,",",Sheet1!K8,",",Sheet1!M8,",",Sheet1!N8,",",Sheet1!O8,",",Sheet1!Q8,",",Sheet1!R8,",",Sheet1!S8,",N'",Sheet1!T8,"',","Null",",","Null",$B$2,"),") -> (N'ANTERO RESOURCES Corp',2019,15197569,8226826,6970743,4408690,5395735,-987045,-340129,-1.11,1103458,-1041490,61968,557564,2.88,-2.59459459459459,-0.0223804873003044,N'NASDAQ',Null,Null ,CURRENT_TIMESTAMP, N'Mohan Hanumantha',CURRENT_TIMESTAMP, N'Mohan Hanumantha'),
A9: =CONCATENATE("(N","'",Sheet1!A9,"',",Sheet1!B9,",",Sheet1!C9,",",SQL!D9,Sheet1!D9,",",Sheet1!E9,",",Sheet1!F9,",",Sheet1!G9,",",Sheet1!H9,",",Sheet1!I9,",",Sheet1!J9,",",Sheet1!K9,",",Sheet1!M9,",",Sheet1!N9,",",Sheet1!O9,",",Sheet1!Q9,",",Sheet1!R9,",",Sheet1!S9,",N'",Sheet1!T9,"',","Null",",","Null",$B$2,"),") -> (N'ANTERO RESOURCES Corp',2020,13150845,7060574,6090271,3491699,4445146,-953447,-1267897,-4.65,735640,-530061,205579,-205579,5.57,-1.19784946236559,-0.0964118275289535,N'NASDAQ',Null,Null ,CURRENT_TIMESTAMP, N'Mohan Hanumantha',CURRENT_TIMESTAMP, N'Mohan Hanumantha'),
A10: =CONCATENATE("(N","'",Sheet1!A10,"',",Sheet1!B10,",",Sheet1!C10,",",SQL!D10,Sheet1!D10,",",Sheet1!E10,",",Sheet1!F10,",",Sheet1!G10,",",Sheet1!H10,",",Sheet1!I10,",",Sheet1!J10,",",Sheet1!K10,",",Sheet1!M10,",",Sheet1!N10,",",Sheet1!O10,",",Sheet1!Q10,",",Sheet1!R10,",",Sheet1!S10,",N'",Sheet1!T10,"',","Null",",","Null",$B$2,"),") -> (N'ANTERO RESOURCES Corp',2021,13896528,7830436,6066092,4619432,4595572,23860,-186899,-0.61,1660116,-710784,949332,-949332,17.33,-28.4098360655738,-0.0134493306529516,N'NASDAQ',Null,Null ,CURRENT_TIMESTAMP, N'Mohan Hanumantha',CURRENT_TIMESTAMP, N'Mohan Hanumantha'),
A11: =CONCATENATE("(N","'",Sheet1!A11,"',",Sheet1!B11,",",Sheet1!C11,",",SQL!D11,Sheet1!D11,",",Sheet1!E11,",",Sheet1!F11,",",Sheet1!G11,",",Sheet1!H11,",",Sheet1!I11,",",Sheet1!J11,",",Sheet1!K11,",",Sheet1!M11,",",Sheet1!N11,",",Sheet1!O11,",",Sheet1!Q11,",",Sheet1!R11,",",Sheet1!S11,",N'",Sheet1!T11,"',","Null",",","Null",$B$2,"),") -> (N'ANTERO RESOURCES Corp',2022,14118039,7100885,7017154,7138436,4564531,2573905,1898771,6.18,3051342,-943612,2107730,-2107730,29.95,4.8462783171521,0.134492545317377,N'NASDAQ',Null,Null ,CURRENT_TIMESTAMP, N'Mohan Hanumantha',CURRENT_TIMESTAMP, N'Mohan Hanumantha'),
A12: =CONCATENATE("(N","'",Sheet1!A12,"',",Sheet1!B12,",",Sheet1!C12,",",SQL!D12,Sheet1!D12,",",Sheet1!E12,",",Sheet1!F12,",",Sheet1!G12,",",Sheet1!H12,",",Sheet1!I12,",",Sheet1!J12,",",Sheet1!K12,",",Sheet1!M12,",",Sheet1!N12,",",Sheet1!O12,",",Sheet1!Q12,",",Sheet1!R12,",",Sheet1!S12,",N'",Sheet1!T12,"',","Null",",","Null",$B$2,"),") -> (N'Callon Petroleum',2012,378173,172202,205971,110733,100043,10690,2747,0.07,51290,-93703,-42413,-243,62.9,898.571428571428,0.00726387129699899,N'NASDAQ',Null,Null ,CURRENT_TIMESTAMP, N'Mohan Hanumantha',CURRENT_TIMESTAMP, N'Mohan Hanumantha'),
A13: =CONCATENATE("(N","'",Sheet1!A13,"',",Sheet1!B13,",",Sheet1!C13,",",SQL!D13,Sheet1!D13,",",Sheet1!E13,",",Sheet1!F13,",",Sheet1!G13,",",Sheet1!H13,",",Sheet1!I13,",",Sheet1!J13,",",Sheet1!K13,",",Sheet1!M13,",",Sheet1!N13,",",Sheet1!O13,",",Sheet1!Q13,",",Sheet1!R13,",",Sheet1!S13,",N'",Sheet1!T13,"',","Null",",","Null",$B$2,"),") -> (N'Callon Petroleum',2013,423953,144859,279094,102569,91905,10664,-323,-0.01,54329,-79804,-25475,27348,37,-3700,-0.000761876906166485,N'NASDAQ',Null,Null ,CURRENT_TIMESTAMP, N'Mohan Hanumantha',CURRENT_TIMESTAMP, N'Mohan Hanumantha'),
A14: =CONCATENATE("(N","'",Sheet1!A14,"',",Sheet1!B14,",",Sheet1!C14,",",SQL!D14,Sheet1!D14,",",Sheet1!E14,",",Sheet1!F14,",",Sheet1!G14,",",Sheet1!H14,",",Sheet1!I14,",",Sheet1!J14,",",Sheet1!K14,",",Sheet1!M14,",",Sheet1!N14,",",Sheet1!O14,",",Sheet1!Q14,",",Sheet1!R14,",",Sheet1!S14,",N'",Sheet1!T14,"',","Null",",","Null",$B$2,"),") -> (N'Callon Petroleum',2014,876770,443035,433735,151862,113592,38270,29871,0.67,94387,-452501,-358114,356070,83.7,124.925373134328,0.0340693682493698,N'NASDAQ',Null,Null ,CURRENT_TIMESTAMP, N'Mohan Hanumantha',CURRENT_TIMESTAMP, N'Mohan Hanumantha'),
... A209: =CONCATENATE("(N","'",Sheet1!A209,"',",Sheet1!B209,",",Sheet1!C209,",",SQL!D209,Sheet1!D209,",",Sheet1!E209,",",Sheet1!F209,",",Sheet1!G209,",",Sheet1!H209,",",Sheet1!I209,",",Sheet1!J209,",",Sheet1!K209,",",Sheet1!M209,",",Sheet1!N209,",",Sheet1!O209,",",Sheet1!Q209,",",Sheet1!R209,",",Sheet1!S209,",N'",Sheet1!T209,"',","Null",",","Null",$B$2,"),") -> (N'Vital Energy',2022,2726114,1615368,1110746,1920796,860634,1060162,631512,37.88,829620,-475952,353668,-366031,79,2.08553326293559,0.231652821562121,N'NASDAQ',Null,Null ,CURRENT_TIMESTAMP, N'Mohan Hanumantha',CURRENT_TIMESTAMP, N'Mohan Hanumantha'),

Sheet Sheet2
A15: Chesapeake Energy | B15: 2015 | C15: 2 | D15: pdf
A16: Chesapeake Energy | B16: 2016 | C16: 2 | D16: pdf
A17: Chesapeake Energy | B17: 2017 | C17: 2 | D17: pdf
A18: Chesapeake Energy | B18: 2018 | C18: 2 | D18: pdf
A19: Chesapeake Energy | B19: 2019 | C19: 2 | D19: pdf | E19: https://app.quotemedia.com/data/downloadFiling?webmasterId=101533&ref=114829726&type=PDF&symbol=CHK&companyName=Chesapeake+Energy+Corporation&formType=10-K&dateFiled=2020-02-27&CK=895126
A20: Chesapeake Energy | B20: 2020 | C20: 2 | D20: pdf | E20: https://app.quotemedia.com/data/downloadFiling?webmasterId=101533&ref=115684457&type=PDF&symbol=CHK&companyName=Chesapeake+Energy+Corporation&formType=10-K&dateFiled=2021-03-01&CK=895126
A21: Chesapeake Energy | B21: 2021 | C21: 2 | D21: pdf | E21: https://app.quotemedia.com/data/downloadFiling?webmasterId=101533&ref=116490942&type=PDF&symbol=CHK&companyName=Chesapeake+Energy+Corporation&formType=10-K&dateFiled=2022-02-24&CK=895126
A22: Chesapeake Energy | B22: 2022 | C22: 2 | D22: pdf | E22: https://app.quotemedia.com/data/downloadFiling?webmasterId=101533&ref=117270814&type=PDF&symbol=CHK&companyName=Chesapeake+Energy+Corporation&formType=10-K&dateFiled=2023-02-22&CK=895126
A23: Chord Energy | B23: 2022 | C23: 2 | D23: pdf | E23: https://app.quotemedia.com/data/downloadFiling?webmasterId=101533&ref=117294757&type=PDF&symbol=CHRD&companyName=Chord+Energy+Corporation&formType=10-K&dateFiled=2023-02-28&CK=1486159
A24: Civitas Resources | B24: 2021 | C24: 2 | D24: pdf | E24: https://d18rn0p25nwr6d.cloudfront.net/CIK-0001509589/4d17e6a3-90f7-4278-b108-816836fea1da.pdf
A25: Civitas Resources | B25: 2022 | C25: 2 | D25: pdf | E25: https://d18rn0p25nwr6d.cloudfront.net/CIK-0001509589/5096b438-430b-4152-97bf-72aada14563c.pdf
A26: ConocoPhillips | B26: 2012 | C26: 2 | D26: webpage | E26: https://www.sec.gov/Archives/edgar/data/0001163165/000119312513065426/d452384d10k.htm
A27: ConocoPhillips | B27: 2013 | C27: 2 | D27: webpage | E27: https://www.sec.gov/Archives/edgar/data/0001163165/000119312514066358/d665238d10k.htm
A28: ConocoPhillips | B28: 2014 | C28: 2 | D28: webpage | E28: https://www.sec.gov/Archives/edgar/data/0001163165/000119312515059281/d869001d10k.htm
A29: ConocoPhillips | B29: 2015 | C29: 2 | D29: webpage | E29: https://www.sec.gov/Archives/edgar/data/0001163165/000119312516472901/d145414d10k.htm
A30: ConocoPhillips | B30: 2016 | C30: 2 | D30: webpage | E30: https://www.sec.gov/Archives/edgar/data/0001163165/000119312517050077/d264316d10k.htm
... A209: XTO Energy, Inc. | B209: 2022 | C209: 2 | D209: webpage | E209: https://ir.exxonmobil.com/static-files/7ac1ca73-14ce-4c13-b34d-267d59a2565f
